I'm sorry, but an uncaught exception occurred.

While running game code:
  File "renpy/common/000statements.rpy", line 671, in execute_call_screen
    store._return = renpy.call_screen(name, *args, **kwargs)
FileNotFoundError: [WinError 2] Не удается найти указанный файл: 'C:\\Users\\arsya\\AppData\\Roaming/RenPy/launcher-4\\persistent'

-- Full Traceback ------------------------------------------------------------

Full traceback:
  File "launcher/game/front_page.rpyc", line 246, in script call
  File "launcher/game/front_page.rpyc", line 256, in script
  File "C:\Users\arsya\OneDrive\Рабочий стол\renpy\renpy-8.3.2-sdk\renpy\ast.py", line 1974, in execute
    self.call("execute")
  File "C:\Users\arsya\OneDrive\Рабочий стол\renpy\renpy-8.3.2-sdk\renpy\ast.py", line 1953, in call
    return renpy.statements.call(method, parsed, *args, **kwargs)
  File "C:\Users\arsya\OneDrive\Рабочий стол\renpy\renpy-8.3.2-sdk\renpy\statements.py", line 374, in call
    return method(parsed, *args, **kwargs)
  File "renpy/common/000statements.rpy", line 671, in execute_call_screen
    store._return = renpy.call_screen(name, *args, **kwargs)
  File "C:\Users\arsya\OneDrive\Рабочий стол\renpy\renpy-8.3.2-sdk\renpy\exports\statementexports.py", line 345, in call_screen
    rv = renpy.ui.interact(mouse="screen", type="screen", roll_forward=roll_forward)
  File "C:\Users\arsya\OneDrive\Рабочий стол\renpy\renpy-8.3.2-sdk\renpy\ui.py", line 301, in interact
    rv = renpy.game.interface.interact(roll_forward=roll_forward, **kwargs)
  File "C:\Users\arsya\OneDrive\Рабочий стол\renpy\renpy-8.3.2-sdk\renpy\display\core.py", line 2215, in interact
    repeat, rv = self.interact_core(preloads=preloads, trans_pause=trans_pause, pause=pause, pause_start=pause_start, pause_modal=pause_modal, **kwargs) # type: ignore
  File "C:\Users\arsya\OneDrive\Рабочий стол\renpy\renpy-8.3.2-sdk\renpy\display\core.py", line 3022, in interact_core
    self.idle_frame(can_block, expensive)
  File "C:\Users\arsya\OneDrive\Рабочий стол\renpy\renpy-8.3.2-sdk\renpy\display\core.py", line 2357, in idle_frame
    renpy.persistent.check_update()
  File "C:\Users\arsya\OneDrive\Рабочий стол\renpy\renpy-8.3.2-sdk\renpy\persistent.py", line 397, in check_update
    update()
  File "C:\Users\arsya\OneDrive\Рабочий стол\renpy\renpy-8.3.2-sdk\renpy\persistent.py", line 434, in update
    save()
  File "C:\Users\arsya\OneDrive\Рабочий стол\renpy\renpy-8.3.2-sdk\renpy\persistent.py", line 456, in save
    renpy.loadsave.location.save_persistent(compressed)
  File "C:\Users\arsya\OneDrive\Рабочий стол\renpy\renpy-8.3.2-sdk\renpy\savelocation.py", line 622, in save_persistent
    l.save_persistent(data)
  File "C:\Users\arsya\OneDrive\Рабочий стол\renpy\renpy-8.3.2-sdk\renpy\savelocation.py", line 433, in save_persistent
    self.persistent_mtime = os.path.getmtime(fn)
  File "lib/python3.9/genericpath.py", line 55, in getmtime
FileNotFoundError: [WinError 2] Не удается найти указанный файл: 'C:\\Users\\arsya\\AppData\\Roaming/RenPy/launcher-4\\persistent'

Windows-10-10.0.22631 AMD64
Ren'Py 8.3.2.24090902
Ren'Py Launcher 8.3.2.24090902
Thu Nov 21 20:25:25 2024
